2025-03-14 00:41:02,343 - categories - INFO - Category created successfully: 1
2025-03-14 00:41:02,588 - categories - ERROR - Error creating category: (sqlite3.IntegrityError) UNIQUE constraint failed: categories.name
[SQL: INSERT INTO categories (name, slug, description, parent_id) VALUES (?, ?, ?, ?)]
[parameters: ('Test Category', 'test-category', None, None)]
(Background on this error at: https://sqlalche.me/e/20/gkpj)
Traceback (most recent call last):
  File "/Users/sunguochao/Documents/Development/cursor/demo2/venv/lib/python3.10/site-packages/sqlalchemy/engine/base.py", line 1964, in _exec_single_context
    self.dialect.do_execute(
  File "/Users/sunguochao/Documents/Development/cursor/demo2/venv/lib/python3.10/site-packages/sqlalchemy/engine/default.py", line 942, in do_execute
    cursor.execute(statement, parameters)
sqlite3.IntegrityError: UNIQUE constraint failed: categories.name

The above exception was the direct cause of the following exception:

Traceback (most recent call last):
  File "/Users/sunguochao/Documents/Development/cursor/demo2/backend/app/api/categories.py", line 40, in create_category
    db.commit()
  File "/Users/sunguochao/Documents/Development/cursor/demo2/venv/lib/python3.10/site-packages/sqlalchemy/orm/session.py", line 2032, in commit
    trans.commit(_to_root=True)
  File "<string>", line 2, in commit
  File "/Users/sunguochao/Documents/Development/cursor/demo2/venv/lib/python3.10/site-packages/sqlalchemy/orm/state_changes.py", line 139, in _go
    ret_value = fn(self, *arg, **kw)
  File "/Users/sunguochao/Documents/Development/cursor/demo2/venv/lib/python3.10/site-packages/sqlalchemy/orm/session.py", line 1313, in commit
    self._prepare_impl()
  File "<string>", line 2, in _prepare_impl
  File "/Users/sunguochao/Documents/Development/cursor/demo2/venv/lib/python3.10/site-packages/sqlalchemy/orm/state_changes.py", line 139, in _go
    ret_value = fn(self, *arg, **kw)
  File "/Users/sunguochao/Documents/Development/cursor/demo2/venv/lib/python3.10/site-packages/sqlalchemy/orm/session.py", line 1288, in _prepare_impl
    self.session.flush()
  File "/Users/sunguochao/Documents/Development/cursor/demo2/venv/lib/python3.10/site-packages/sqlalchemy/orm/session.py", line 4353, in flush
    self._flush(objects)
  File "/Users/sunguochao/Documents/Development/cursor/demo2/venv/lib/python3.10/site-packages/sqlalchemy/orm/session.py", line 4488, in _flush
    with util.safe_reraise():
  File "/Users/sunguochao/Documents/Development/cursor/demo2/venv/lib/python3.10/site-packages/sqlalchemy/util/langhelpers.py", line 146, in __exit__
    raise exc_value.with_traceback(exc_tb)
  File "/Users/sunguochao/Documents/Development/cursor/demo2/venv/lib/python3.10/site-packages/sqlalchemy/orm/session.py", line 4449, in _flush
    flush_context.execute()
  File "/Users/sunguochao/Documents/Development/cursor/demo2/venv/lib/python3.10/site-packages/sqlalchemy/orm/unitofwork.py", line 466, in execute
    rec.execute(self)
  File "/Users/sunguochao/Documents/Development/cursor/demo2/venv/lib/python3.10/site-packages/sqlalchemy/orm/unitofwork.py", line 642, in execute
    util.preloaded.orm_persistence.save_obj(
  File "/Users/sunguochao/Documents/Development/cursor/demo2/venv/lib/python3.10/site-packages/sqlalchemy/orm/persistence.py", line 93, in save_obj
    _emit_insert_statements(
  File "/Users/sunguochao/Documents/Development/cursor/demo2/venv/lib/python3.10/site-packages/sqlalchemy/orm/persistence.py", line 1233, in _emit_insert_statements
    result = connection.execute(
  File "/Users/sunguochao/Documents/Development/cursor/demo2/venv/lib/python3.10/site-packages/sqlalchemy/engine/base.py", line 1416, in execute
    return meth(
  File "/Users/sunguochao/Documents/Development/cursor/demo2/venv/lib/python3.10/site-packages/sqlalchemy/sql/elements.py", line 523, in _execute_on_connection
    return connection._execute_clauseelement(
  File "/Users/sunguochao/Documents/Development/cursor/demo2/venv/lib/python3.10/site-packages/sqlalchemy/engine/base.py", line 1638, in _execute_clauseelement
    ret = self._execute_context(
  File "/Users/sunguochao/Documents/Development/cursor/demo2/venv/lib/python3.10/site-packages/sqlalchemy/engine/base.py", line 1843, in _execute_context
    return self._exec_single_context(
  File "/Users/sunguochao/Documents/Development/cursor/demo2/venv/lib/python3.10/site-packages/sqlalchemy/engine/base.py", line 1983, in _exec_single_context
    self._handle_dbapi_exception(
  File "/Users/sunguochao/Documents/Development/cursor/demo2/venv/lib/python3.10/site-packages/sqlalchemy/engine/base.py", line 2352, in _handle_dbapi_exception
    raise sqlalchemy_exception.with_traceback(exc_info[2]) from e
  File "/Users/sunguochao/Documents/Development/cursor/demo2/venv/lib/python3.10/site-packages/sqlalchemy/engine/base.py", line 1964, in _exec_single_context
    self.dialect.do_execute(
  File "/Users/sunguochao/Documents/Development/cursor/demo2/venv/lib/python3.10/site-packages/sqlalchemy/engine/default.py", line 942, in do_execute
    cursor.execute(statement, parameters)
sqlalchemy.exc.IntegrityError: (sqlite3.IntegrityError) UNIQUE constraint failed: categories.name
[SQL: INSERT INTO categories (name, slug, description, parent_id) VALUES (?, ?, ?, ?)]
[parameters: ('Test Category', 'test-category', None, None)]
(Background on this error at: https://sqlalche.me/e/20/gkpj)
2025-03-14 00:41:02,835 - categories - INFO - Found 2 categories
2025-03-14 00:47:04,609 - categories - INFO - Found 0 categories
